Workbook

Sheet 里程碑总览
A1: 耄耋改名 · 技术方案实施排期总览
A2: 人日 = 3 小时有效投入；日历天 = 人日 × 比率（见「假设与口径」）；结束日期 = 起始日期 + 累计日历天 − 1；状态由「任务明细」自动汇总，不需手填
A3: 里程碑 | B3: 阶段 | C3: 主要内容 | D3: 人日 | E3: 累计人日 | F3: 占总量比 | G3: 折算日历天 | H3: 开始日期 | I3: 结束日期 | J3: 依赖 | K3: 主要交付物 | L3: 状态 | M3: 工作量可视化
A4: MS-1 | B4: 引擎先行 | C4: 规则引擎 + 冲突检测 + 扩展名保护 + 两阶段改名 + 存储与撤销服务；命令行可验证 | D4: =SUMIF(任务明细!$B$4:$B$48,$A4,任务明细!$E$4:$E$48) | E4: =SUM($D$4:D4) | F4: =IF($E$9=0,"",D4/$E$9) | G4: =ROUND(E4*假设与口径!$B$7,0) | H4: =假设与口径!$B$4 | I4: =假设与口径!$B$4+$G4-1 | J4: — | K4: 可命令行验证的改名内核；引擎单测覆盖率 ≥ 90% | L4: =IF(COUNTIF(任务明细!$B$4:$B$48,$A4)=0,"未开始",IF(COUNTIFS(任务明细!$B$4:$B$48,$A4,任务明细!$H$4:$H$48,"已完成")=COUNTIF(任务明细!$B$4:$B$48,$A4),"已完成",IF(COUNTIFS(任务明细!$B$4:$B$48,$A4,任务明细!$H$4:$H$48,"未开始")=COUNTIF(任务明细!$B$4:$B$48,$A4),"未开始","进行中"))) | M4: =REPT("█",MAX(1,ROUND($D4/MAX($D$4:$D$8)*18,0)))
A5: MS-2 | B5: 界面成型 | C5: SCR-01 主窗口 UI + 文件列表 + 规则区 + 实时预览（Worker）+ 虚拟滚动 | D5: =SUMIF(任务明细!$B$4:$B$48,$A5,任务明细!$E$4:$E$48) | E5: =SUM($D$4:D5) | F5: =IF($E$9=0,"",D5/$E$9) | G5: =ROUND(E5*假设与口径!$B$7,0) | H5: =I4+1 | I5: =假设与口径!$B$4+$G5-1 | J5: MS-1 | K5: 能用的界面（无形象），可完成一次完整改名 | L5: =IF(COUNTIF(任务明细!$B$4:$B$48,$A5)=0,"未开始",IF(COUNTIFS(任务明细!$B$4:$B$48,$A5,任务明细!$H$4:$H$48,"已完成")=COUNTIF(任务明细!$B$4:$B$48,$A5),"已完成",IF(COUNTIFS(任务明细!$B$4:$B$48,$A5,任务明细!$H$4:$H$48,"未开始")=COUNTIF(任务明细!$B$4:$B$48,$A5),"未开始","进行中"))) | M5: =REPT("█",MAX(1,ROUND($D5/MAX($D$4:$D$8)*18,0)))
A6: MS-3 | B6: 注入灵魂 | C6: 耄耋 5 状态动画 + ST-03 咬名字 + 音效 + 微动效 + 减少动画开关 | D6: =SUMIF(任务明细!$B$4:$B$48,$A6,任务明细!$E$4:$E$48) | E6: =SUM($D$4:D6) | F6: =IF($E$9=0,"",D6/$E$9) | G6: =ROUND(E6*假设与口径!$B$7,0) | H6: =I5+1 | I6: =假设与口径!$B$4+$G6-1 | J6: MS-2 | K6: 有灵魂的 UI；动作歧义自查通过 | L6: =IF(COUNTIF(任务明细!$B$4:$B$48,$A6)=0,"未开始",IF(COUNTIFS(任务明细!$B$4:$B$48,$A6,任务明细!$H$4:$H$48,"已完成")=COUNTIF(任务明细!$B$4:$B$48,$A6),"已完成",IF(COUNTIFS(任务明细!$B$4:$B$48,$A6,任务明细!$H$4:$H$48,"未开始")=COUNTIF(任务明细!$B$4:$B$48,$A6),"未开始","进行中"))) | M6: =REPT("█",MAX(1,ROUND($D6/MAX($D$4:$D$8)*18,0)))
A7: MS-4 | B7: 安全闭环 | C7: 拖拽（P0）+ 系统对话框 + 执行/取消/回滚 + 三个弹窗 + 历史页 + 异常态全覆盖 | D7: =SUMIF(任务明细!$B$4:$B$48,$A7,任务明细!$E$4:$E$48) | E7: =SUM($D$4:D7) | F7: =IF($E$9=0,"",D7/$E$9) | G7: =ROUND(E7*假设与口径!$B$7,0) | H7: =I6+1 | I7: =假设与口径!$B$4+$G7-1 | J7: MS-2 | K7: 安全完整版；TC-07 冲突不覆盖可验证 | L7: =IF(COUNTIF(任务明细!$B$4:$B$48,$A7)=0,"未开始",IF(COUNTIFS(任务明细!$B$4:$B$48,$A7,任务明细!$H$4:$H$48,"已完成")=COUNTIF(任务明细!$B$4:$B$48,$A7),"已完成",IF(COUNTIFS(任务明细!$B$4:$B$48,$A7,任务明细!$H$4:$H$48,"未开始")=COUNTIF(任务明细!$B$4:$B$48,$A7),"未开始","进行中"))) | M7: =REPT("█",MAX(1,ROUND($D7/MAX($D$4:$D$8)*18,0)))
A8: MS-5 | B8: 打包发布 | C8: electron-builder + NSIS + 体积优化 + 全量回归 + 真机验证 + 开源整理 | D8: =SUMIF(任务明细!$B$4:$B$48,$A8,任务明细!$E$4:$E$48) | E8: =SUM($D$4:D8) | F8: =IF($E$9=0,"",D8/$E$9) | G8: =ROUND(E8*假设与口径!$B$7,0) | H8: =I7+1 | I8: =假设与口径!$B$4+$G8-1 | J8: MS-3 / MS-4 | K8: 可安装的 exe（安装包实测体积已记录） | L8: =IF(COUNTIF(任务明细!$B$4:$B$48,$A8)=0,"未开始",IF(COUNTIFS(任务明细!$B$4:$B$48,$A8,任务明细!$H$4:$H$48,"已完成")=COUNTIF(任务明细!$B$4:$B$48,$A8),"已完成",IF(COUNTIFS(任务明细!$B$4:$B$48,$A8,任务明细!$H$4:$H$48,"未开始")=COUNTIF(任务明细!$B$4:$B$48,$A8),"未开始","进行中"))) | M8: =REPT("█",MAX(1,ROUND($D8/MAX($D$4:$D$8)*18,0)))
A9: 合计 | C9: 5 个里程碑 / 45 项任务 | D9: =SUM(D4:D8) | E9: =E8 | F9: =IF($E$9=0,"",SUM(F4:F8)) | G9: =G8 | I9: =I8
A11: 总体进度（随「任务明细」状态自动计算）
A12: 总人日 | B12: =SUM(任务明细!$E$4:$E$48)
A13: 已完成人日 | B13: =SUMIF(任务明细!$H$4:$H$48,"已完成",任务明细!$E$4:$E$48)
A14: 完成率 | B14: =IF($B$12=0,"",$B$13/$B$12)
A15: 预计完成日（无缓冲） | B15: =假设与口径!$B$4+ROUND($B$12*假设与口径!$B$7,0)-1
A16: 预计完成日（含 20% 缓冲） | B16: =假设与口径!$B$4+ROUND($B$12*假设与口径!$B$7*假设与口径!$B$8,0)-1

Sheet 任务明细
A1: 耄耋改名 · 实施任务明细（45 项任务）
A2: 「状态」请下拉选择；「累计人日」「计划完成日」为公式列，不要手改。计划完成日 = 起始日期 + 累计人日 × 比率 − 1（参数见「假设与口径」）
A3: 任务编号 | B3: 里程碑 | C3: 任务名称 | D3: 所属模块 | E3: 人日 | F3: 依赖 | G3: 验收标志 | H3: 状态 | I3: 累计人日 | J3: 计划完成日 | K3: 备注
A4: T-1.1 | B4: MS-1 | C4: 工程脚手架（electron-vite + TS + Vue3 + Pinia + Vitest + ESLint 依赖方向规则） | D4: 基础设施 | E4: 1 | F4: — | G4: npm run dev 可启动；反向 import 被 lint 拦住 | H4: 已完成 | I4: =SUM($E$4:E4) | J4: =假设与口径!$B$4+ROUND(I4*假设与口径!$B$7,0)-1 | K4: tsconfig 开 strict
A5: T-1.2 | B5: MS-1 | C5: 共享层类型 / 常量 / 通道名 / 错误码 | D5: shared | E5: 0.5 | F5: T-1.1 | G5: 类型编译通过；通道名与接口文档 §3 一致 | H5: 已完成 | I5: =SUM($E$4:E5) | J5: =假设与口径!$B$4+ROUND(I5*假设与口径!$B$7,0)-1
A6: T-1.3 | B6: MS-1 | C6: 路径工具 + 名称拆分与扩展名保护 | D6: shared | E6: 1 | F6: T-1.2 | G6: 单测 U-05 / U-06；EX-07 全部细则逐条覆盖 | H6: 已完成 | I6: =SUM($E$4:E6) | J6: =假设与口径!$B$4+ROUND(I6*假设与口径!$B$7,0)-1 | K6: 含 .gitignore / 结尾点 / 全角点边界
A7: T-1.4 | B7: MS-1 | C7: 规则引擎三模式 + 变量去重 + 组合公式 A/B/C/D | D7: shared | E7: 2 | F7: T-1.3 | G7: 单测 U-07 / U-08；TC-03 / TC-04 / TC-06 | H7: 已完成 | I7: =SUM($E$4:E7) | J7: =假设与口径!$B$4+ROUND(I7*假设与口径!$B$7,0)-1 | K7: 公式以 PRD §4.2.5 表格为准
A8: T-1.5 | B8: MS-1 | C8: 差异高亮算法（最长公共前缀 / 后缀） | D8: shared | E8: 0.5 | F8: T-1.3 | G8: 单测 U-14 覆盖全部边界情形 | H8: 已完成 | I8: =SUM($E$4:E8) | J8: =假设与口径!$B$4+ROUND(I8*假设与口径!$B$7,0)-1
A9: T-1.6 | B9: MS-1 | C9: 校验器（非法字符 / 保留名 / 结尾点 / 超长 / 空名） | D9: shared | E9: 0.5 | F9: T-1.3 | G9: 单测 U-09 / U-10；TC-13 / TC-14 | H9: 已完成 | I9: =SUM($E$4:E9) | J9: =假设与口径!$B$4+ROUND(I9*假设与口径!$B$7,0)-1 | K9: 保留名检查为本方案新增
A10: T-1.7 | B10: MS-1 | C10: 冲突检测（批次内 + 磁盘 + case-only + 快照剔除源名称） | D10: shared | E10: 1.5 | F10: T-1.4 | G10: 单测 U-02 / U-04 / U-11 / U-15；TC-07 | H10: 已完成 | I10: =SUM($E$4:E10) | J10: =假设与口径!$B$4+ROUND(I10*假设与口径!$B$7,0)-1 | K10: 最高风险模块，必须写透
A11: T-1.8 | B11: MS-1 | C11: 两阶段改名执行器（safeRename / 回滚 / 取消） | D11: 主进程 | E11: 2.5 | F11: T-1.7 | G11: 单测 U-01 / U-03；目标已存在时文件字节不变 | H11: 已完成 | I11: =SUM($E$4:E11) | J11: =假设与口径!$B$4+ROUND(I11*假设与口径!$B$7,0)-1 | K11: ESLint 禁止裸 fs.rename
A12: T-1.9 | B12: MS-1 | C12: 存储服务（原子写 / FIFO 淘汰 / 损坏恢复 / 写入队列） | D12: 主进程 | E12: 1.5 | F12: T-1.2 | G12: 单测 U-16（21 次改写后仅留 20 条）；模拟中断不损坏原文件 | H12: 已完成 | I12: =SUM($E$4:E12) | J12: =假设与口径!$B$4+ROUND(I12*假设与口径!$B$7,0)-1
A13: T-1.10 | B13: MS-1 | C13: 撤销服务（倒序 / 部分失败跳过 / 全部撤销） | D13: 主进程 | E13: 1 | F13: T-1.9 | G13: 单测 U-12 / U-13；TC-09 / TC-11 | H13: 已完成 | I13: =SUM($E$4:E13) | J13: =假设与口径!$B$4+ROUND(I13*假设与口径!$B$7,0)-1
A14: T-1.11 | B14: MS-1 | C14: CLI 验证脚本 + 引擎单测补齐 | D14: 测试 | E14: 1 | F14: T-1.4 ~ T-1.10 | G14: 覆盖率 ≥ 90%；1000 项预览 < 200ms | H14: 已完成 | I14: =SUM($E$4:E14) | J14: =假设与口径!$B$4+ROUND(I14*假设与口径!$B$7,0)-1 | K14: MS-1 的核心交付物
A15: T-2.1 | B15: MS-2 | C15: 设计令牌落地（tokens.css / tokens.ts） | D15: 渲染层 | E15: 0.5 | F15: T-1.1 | G15: 色值只出现在 tokens.css；间距全在 4px 台阶 | H15: 已完成 | I15: =SUM($E$4:E15) | J15: =假设与口径!$B$4+ROUND(I15*假设与口径!$B$7,0)-1
A16: T-2.2 | B16: MS-2 | C16: 窗口外壳与自绘标题栏（三按钮 + 拖拽区 + 尺寸记忆） | D16: 渲染层 / 主进程 | E16: 2 | F16: T-2.1 | G16: TC-17；恢复位置时窗口必落在可见屏幕内 | H16: 已完成 | I16: =SUM($E$4:E16) | J16: =假设与口径!$B$4+ROUND(I16*假设与口径!$B$7,0)-1 | K16: userData 目录名改为英文
A17: T-2.3 | B17: MS-2 | C17: 左栏形象区占位 + 操作区三按钮 | D17: 渲染层 | E17: 1 | F17: T-2.1 | G17: 三按钮样式符合设计规范 §4.1 | H17: 已完成 | I17: =SUM($E$4:E17) | J17: =假设与口径!$B$4+ROUND(I17*假设与口径!$B$7,0)-1
A18: T-2.4 | B18: MS-2 | C18: 文件列表（行渲染 / 计数 / 全选 / 行内删除 / 空态） | D18: 渲染层 | E18: 2 | F18: T-2.3 | G18: EL-030 ~ EL-037 全部元素与状态 | H18: 已完成 | I18: =SUM($E$4:E18) | J18: =假设与口径!$B$4+ROUND(I18*假设与口径!$B$7,0)-1
A19: T-2.5 | B19: MS-2 | C19: 差异高亮渲染（DiffText 组件） | D19: 渲染层 | E19: 1 | F19: T-1.5 / T-2.4 | G19: TC-03；变化片段橘色高亮 + 原片段删除线 | H19: 已完成 | I19: =SUM($E$4:E19) | J19: =假设与口径!$B$4+ROUND(I19*假设与口径!$B$7,0)-1
A20: T-2.6 | B20: MS-2 | C20: 规则区（页签 + 三模式表单 + 联动置灰） | D20: 渲染层 | E20: 2.5 | F20: T-2.3 | G20: EL-040 ~ EL-055；规则化模式下隐藏 EL-044 | H20: 已完成 | I20: =SUM($E$4:E20) | J20: =假设与口径!$B$4+ROUND(I20*假设与口径!$B$7,0)-1
A21: T-2.7 | B21: MS-2 | C21: 预览 Worker 接入 + 200ms 防抖 + 过期结果丢弃 | D21: 渲染层 | E21: 1.5 | F21: T-1.4 / T-2.6 | G21: 1000 项预览 ≤ 200ms；快速连打 20 字不闪动 | H21: 已完成 | I21: =SUM($E$4:E21) | J21: =假设与口径!$B$4+ROUND(I21*假设与口径!$B$7,0)-1
A22: T-2.8 | B22: MS-2 | C22: 虚拟滚动（> 500 行，固定行高 36px） | D22: 渲染层 | E22: 1.5 | F22: T-2.4 | G22: 10000 项滚动不掉帧；全选基于 id 而非 DOM 索引 | H22: 已完成 | I22: =SUM($E$4:E22) | J22: =假设与口径!$B$4+ROUND(I22*假设与口径!$B$7,0)-1
A23: T-2.9 | B23: MS-2 | C23: 状态栏（状态点 / 文案规则 / 进度条） | D23: 渲染层 | E23: 1 | F23: T-2.4 | G23: 交互说明 §11.2 全部文案分支命中 | H23: 已完成 | I23: =SUM($E$4:E23) | J23: =假设与口径!$B$4+ROUND(I23*假设与口径!$B$7,0)-1
A24: T-2.10 | B24: MS-2 | C24: 按钮状态矩阵（开始改名置灰逻辑） | D24: 渲染层 | E24: 0.5 | F24: T-2.7 | G24: EX-11 / EX-12 置灰正确 | H24: 已完成 | I24: =SUM($E$4:E24) | J24: =假设与口径!$B$4+ROUND(I24*假设与口径!$B$7,0)-1
A25: T-2.11 | B25: MS-2 | C25: 键盘与无障碍（快捷键 + 焦点顺序 + 减少动画开关） | D25: 渲染层 | E25: 1 | F25: T-2.2 | G25: 交互说明 §9 全部按键生效 | H25: 已完成 | I25: =SUM($E$4:E25) | J25: =假设与口径!$B$4+ROUND(I25*假设与口径!$B$7,0)-1
A26: T-3.1 | B26: MS-3 | C26: 形象资源接入（6 分组 + manifest.json 一键替换机制） | D26: 渲染层 | E26: 1.5 | F26: T-2.3 | G26: 换掉 cats/ 目录即可换形象，代码零改动 | H26: 已完成 | I26: =SUM($E$4:E26) | J26: =假设与口径!$B$4+ROUND(I26*假设与口径!$B$7,0)-1 | K26: 形象仍为占位
A27: T-3.2 | B27: MS-3 | C27: 状态机（优先级 / 会话约束 / 回落定时器清理） | D27: 渲染层 | E27: 1.5 | F27: T-3.1 | G27: ST-03 不被 ST-02 抢占；无幽灵定时器 | H27: 已完成 | I27: =SUM($E$4:E27) | J27: =假设与口径!$B$4+ROUND(I27*假设与口径!$B$7,0)-1
A28: T-3.3 | B28: MS-3 | C28: ST-01 / ST-02 / ST-04 / ST-05 动画 | D28: 渲染层 | E28: 2 | F28: T-3.2 | G28: 四状态文案与动效符合设计规范 §6.2 | H28: 已完成 | I28: =SUM($E$4:E28) | J28: =假设与口径!$B$4+ROUND(I28*假设与口径!$B$7,0)-1
A29: T-3.4 | B29: MS-3 | C29: ST-03 咬名字动画（卡片队列 + 8 关键点时序） | D29: 渲染层 | E29: 3 | F29: T-3.2 | G29: 交互说明 §7.3 时序逐点对齐；离开即停无残影 | H29: 已完成 | I29: =SUM($E$4:E29) | J29: =假设与口径!$B$4+ROUND(I29*假设与口径!$B$7,0)-1 | K29: 工作量最大的一项
A30: T-3.5 | B30: MS-3 | C30: 音效接入 + 开关 | D30: 渲染层 | E30: 0.5 | F30: T-3.3 | G30: 成功「叮」/ 失败「噗」；开关即时生效 | H30: 已完成 | I30: =SUM($E$4:E30) | J30: =假设与口径!$B$4+ROUND(I30*假设与口径!$B$7,0)-1
A31: T-3.6 | B31: MS-3 | C31: 「动作不得有歧义」自查 + 非项目成员观看 | D31: 验收 | E31: 0.5 | F31: T-3.4 | G31: 至少 1 位非项目成员确认无歧义 | H31: 已完成 | I31: =SUM($E$4:E31) | J31: =假设与口径!$B$4+ROUND(I31*假设与口径!$B$7,0)-1 | K31: PRD §4.6.3 硬约束
A32: T-4.1 | B32: MS-4 | C32: 系统对话框通道（pickFiles / pickDirectory） | D32: 主进程 | E32: 0.5 | F32: T-2.2 | G32: TC-02：文件夹只加本身，不递归内部文件 | H32: 已完成 | I32: =SUM($E$4:E32) | J32: =假设与口径!$B$4+ROUND(I32*假设与口径!$B$7,0)-1
A33: T-4.2 | B33: MS-4 | C33: 路径解析入列（resolvePaths + 目录快照 + stats 五项） | D33: 主进程 | E33: 1.5 | F33: T-4.1 | G33: EX-08 / EX-09 / EX-13 计数正确 | H33: 已完成 | I33: =SUM($E$4:E33) | J33: =假设与口径!$B$4+ROUND(I33*假设与口径!$B$7,0)-1 | K33: symlink 指向目录时 isDir 判定正确
A34: T-4.3 | B34: MS-4 | C34: 拖拽入列（计数蒙层 / 拒绝态 / 去重 / 落区高亮） | D34: 渲染层 | E34: 1.5 | F34: T-4.2 | G34: TC-01；dragenter 计数归零才隐藏蒙层 | H34: 已完成 | I34: =SUM($E$4:E34) | J34: =假设与口径!$B$4+ROUND(I34*假设与口径!$B$7,0)-1
A35: T-4.4 | B35: MS-4 | C35: 执行流程接入（进度事件 + 取消 + 回滚 UI） | D35: 渲染层 / 主进程 | E35: 2 | F35: T-2.7 / T-1.8 | G35: TC-15；取消后已改项全部回滚为原名 | H35: 已完成 | I35: =SUM($E$4:E35) | J35: =假设与口径!$B$4+ROUND(I35*假设与口径!$B$7,0)-1
A36: T-4.5 | B36: MS-4 | C36: SCR-03 结果弹窗（摘要 / 示例 / 异常清单） | D36: 渲染层 | E36: 1.5 | F36: T-4.4 | G36: 异常清单 200 条截断并显示总数 | H36: 已完成 | I36: =SUM($E$4:E36) | J36: =假设与口径!$B$4+ROUND(I36*假设与口径!$B$7,0)-1 | K36: recordSaved=false 时必须明确警告
A37: T-4.6 | B37: MS-4 | C37: SCR-04 冲突弹窗 + 「自动加序号」联动 | D37: 渲染层 | E37: 1 | F37: T-4.4 | G37: TC-08；默认按钮为「先不改（推荐）」 | H37: 已完成 | I37: =SUM($E$4:E37) | J37: =假设与口径!$B$4+ROUND(I37*假设与口径!$B$7,0)-1
A38: T-4.7 | B38: MS-4 | C38: SCR-05 二次确认（四类文案） | D38: 渲染层 | E38: 1 | F38: T-4.4 | G38: 设计规范 §5.4 四类文案逐条对上 | H38: 已完成 | I38: =SUM($E$4:E38) | J38: =假设与口径!$B$4+ROUND(I38*假设与口径!$B$7,0)-1
A39: T-4.8 | B39: MS-4 | C39: SCR-02 历史页（两态卡片 + 单条撤销 + 全部撤销 + 清空历史） | D39: 渲染层 | E39: 2 | F39: T-1.10 | G39: TC-09 / TC-10 / TC-11 | H39: 已完成 | I39: =SUM($E$4:E39) | J39: =假设与口径!$B$4+ROUND(I39*假设与口径!$B$7,0)-1 | K39: 「清空历史」为新增；超上限淘汰须显式提示（DEC-09）
A40: T-4.9 | B40: MS-4 | C40: 异常态全覆盖（EX-01 ~ EX-14 界面表现） | D40: 渲染层 | E40: 1.5 | F40: T-4.5 | G40: 文案全部取自 MD_ERROR_TEXT，无硬编码 | H40: 已完成 | I40: =SUM($E$4:E40) | J40: =假设与口径!$B$4+ROUND(I40*假设与口径!$B$7,0)-1
...

Sheet 验收用例对照
A1: 验收用例 · 任务归属对照（PRD 第 10 章 TC-01 ~ TC-18）
A2: 用例编号 | B2: 用例名称 | C2: 对应功能 | D2: 主要相关任务 | E2: 可自动化 | F2: 状态 | G2: 验收要点
A3: TC-01 | B3: 拖拽 / 按钮入列 | C3: F-07 · F-01 | D3: T-4.3 · T-4.2 | E3: 部分 | F3: 通过 | G3: 100 个文件全部入列，ST-02 触发
A4: TC-02 | B4: 添加文件夹不递归 | C4: DEC-01 | D4: T-4.1 | E4: 是 | F4: 通过 | G4: 只加入文件夹本身，不展开内部
A5: TC-03 | B5: 删除字符 + 变化高亮 | C5: F-03 · F-08 | D5: T-1.4 · T-2.5 | E5: 是 | F5: 通过 | G5: abc广告.txt → abc.txt 且变化片段高亮
A6: TC-04 | B6: 替换字符 | C6: F-04 | D6: T-1.4 | E6: 是 | F6: 通过 | G6: 会议纪要-最终版 → 会议纪要-定稿
A7: TC-05 | B7: 扩展名保护 | C7: EX-07 | D7: T-1.3 | E7: 是 | F7: 通过 | G7: 删除「.」后扩展名前的点保留
A8: TC-06 | B8: 规则化组合（日期 + 序号 + 不保留原名） | C8: F-05 | D8: T-1.4 | E8: 是 | F8: 通过 | G8: 公式以 PRD §4.2.5 表格为准
A9: TC-07 | B9: 冲突不覆盖 | C9: F-16 · DEC-05 | D9: T-1.7 · T-1.8 | E9: 是 | F9: 通过 | G9: 硬指标；磁盘文件必须零损失
A10: TC-08 | B10: 自动加序号 | C10: F-16 | D10: T-1.7 · T-4.6 | E10: 是 | F10: 通过 | G10: 生成 报告_1.docx / 报告_2.docx
A11: TC-09 | B11: 撤销单条 | C11: F-09 | D11: T-1.10 · T-4.8 | E11: 是 | F11: 通过 | G11: 文件名全部还原，该条转「已撤销」
A12: TC-10 | B12: 历史 20 条上限 | C12: DEC-06 | D12: T-1.9 | E12: 是 | F12: 通过 | G12: 与总条数上限的取舍见数据库设计 §4.4.4
A13: TC-11 | B13: 全部撤销 | C13: F-09 | D13: T-4.8 | E13: 是 | F13: 通过 | G13: 倒序逐条撤销，末了汇总提示
... A20: TC-18 | B20: 空列表保护 | C20: EX-11 | D20: T-2.10 | E20: 是 | F20: 通过 | G20: 按钮置灰不可点

Sheet 假设与口径
A1: 排期口径与假设（本页是全部日期公式的参数来源，改动这里会联动全局）
A3: 参数 | B3: 值 | C3: 说明
A4: 项目起始日期 | B4: 46279 | C4: 第一个工作日（周一）。前一日为方案定稿日
A5: 每天有效投入（小时） | B5: 2.5 | C5: 业余节奏：工作日晚上为主，周末可加量
A6: 1 人日 = 小时 | B6: 3 | C6: 人日定义口径；已按 AI 辅助开发的速度折算
A7: 日历天 / 人日 | B7: =B6/B5 | C7: 由「1 人日小时数 ÷ 每天有效投入」推导，不手填
A8: 缓冲系数 | B8: 1.2 | C8: 20% 缓冲，吸收调试、返工与踩坑时间
A10: 总人日 | B10: =SUM(任务明细!$E$4:$E$48)
A11: 折算总日历天（无缓冲） | B11: =ROUND(B10*B7,0)
A12: 预计完成日（无缓冲） | B12: =B4+B11-1
A13: 预计完成日（含 20% 缓冲） | B13: =B4+ROUND(B10*B7*B8,0)-1
A17: 口径说明
A18: · 人日定义 | B18: 1 人日 = 3 小时有效投入，已按 AI 辅助开发（AI 写码、人做决策与验证）的速度折算。
A19: · 日历天折算 | B19: 日历天 = 人日 × (3 小时 ÷ 每天有效投入)。按每天 2.5 小时计，1 人日 ≈ 1.2 个日历天。
A20: · 里程碑衔接 | B20: 里程碑顺序执行。MS-3 与 MS-4 都只依赖 MS-2，理论上可并行；但由同一人推进，故按串行排。
A21: · 未含缓冲的完成日 | B21: 所有里程碑日期为「无缓冲」推演值；含 20% 缓冲的完成日见上方汇总最后一行。
A23: 按当前参数推演的关键日期
A24: · MS-1 引擎先行 | B24: 无依赖，最先开始。完成后即可用命令行验证改名引擎（PRD 的 MS-1 交付物）。
A25: · MS-2 界面成型 | B25: 依赖 MS-1。界面上线后可完成第一次完整改名。
A26: · MS-3 注入灵魂 | B26: 依赖 MS-2。含全项目工作量最大的单项（T-3.4 咬名字动画，3 人日）。
A27: · MS-4 安全闭环 | B27: 依赖 MS-2。安全底线（冲突不覆盖 / 撤销）到此可端到端验证。
A28: · MS-5 打包发布 | B28: 依赖 MS-3 与 MS-4。体积实测若超 100MB，需回头评审 PRD 的这一指标。
A30: 本排期表不含的内容
A31: · P1 功能 | B31: 正则规则（F-10）、多规则链、大小写转换（F-11）均不在 MVP 排期内。
A32: · P2 功能 | B32: 模板库（F-12）、完整历史（F-13）、深色模式（F-14）、命令行模式（F-15）不在排期内。
A33: · 美术终稿 | B33: 猫咪形象为可替换占位，版权为 Accepted Risk；最终美术稿的产出时间不在本表内。
